[2025-07-13T14:15:40.860+0000] {local_task_job_runner.py:123} INFO - ::group::Pre task execution logs
[2025-07-13T14:15:40.885+0000] {taskinstance.py:2614} INFO - Dependencies all met for dep_context=non-requeueable deps ti=<TaskInstance: fraud_detection_training.execute_training manual__2025-07-13T14:15:38.902575+00:00 [queued]>
[2025-07-13T14:15:40.898+0000] {taskinstance.py:2614} INFO - Dependencies all met for dep_context=requeueable deps ti=<TaskInstance: fraud_detection_training.execute_training manual__2025-07-13T14:15:38.902575+00:00 [queued]>
[2025-07-13T14:15:40.898+0000] {taskinstance.py:2867} INFO - Starting attempt 1 of 1
[2025-07-13T14:15:40.914+0000] {taskinstance.py:2890} INFO - Executing <Task(PythonOperator): execute_training> on 2025-07-13 14:15:38.902575+00:00
[2025-07-13T14:15:40.920+0000] {warnings.py:112} WARNING - /home/***/.local/lib/python3.12/site-packages/***/task/task_runner/standard_task_runner.py:70: DeprecationWarning: This process (pid=2762) is multi-threaded, use of fork() may lead to deadlocks in the child.
  pid = os.fork()

[2025-07-13T14:15:40.922+0000] {standard_task_runner.py:72} INFO - Started process 2763 to run task
[2025-07-13T14:15:40.922+0000] {standard_task_runner.py:104} INFO - Running: ['***', 'tasks', 'run', 'fraud_detection_training', 'execute_training', 'manual__2025-07-13T14:15:38.902575+00:00', '--job-id', '34', '--raw', '--subdir', 'DAGS_FOLDER/fraud_detection_training_dag.py', '--cfg-path', '/tmp/tmp1289pt20']
[2025-07-13T14:15:40.923+0000] {standard_task_runner.py:105} INFO - Job 34: Subtask execute_training
[2025-07-13T14:15:40.968+0000] {task_command.py:467} INFO - Running <TaskInstance: fraud_detection_training.execute_training manual__2025-07-13T14:15:38.902575+00:00 [running]> on host 2d98890b302a
[2025-07-13T14:15:41.065+0000] {taskinstance.py:3134} INFO - Exporting env vars: AIRFLOW_CTX_DAG_OWNER='datamasterylab.com' AIRFLOW_CTX_DAG_ID='fraud_detection_training' AIRFLOW_CTX_TASK_ID='execute_training' AIRFLOW_CTX_EXECUTION_DATE='2025-07-13T14:15:38.902575+00:00' AIRFLOW_CTX_TRY_NUMBER='1' AIRFLOW_CTX_DAG_RUN_ID='manual__2025-07-13T14:15:38.902575+00:00'
[2025-07-13T14:15:41.065+0000] {taskinstance.py:732} INFO - ::endgroup::
[2025-07-13T14:15:44.616+0000] {warnings.py:112} WARNING - /opt/***/dags/fraud_detection_training.py:45: UserWarning: The numpy.array_api submodule is still experimental. See NEP 47.
  from numpy.array_api import astype

[2025-07-13T14:15:44.658+0000] {fraud_detection_training_dag.py:23} INFO - Initializing fraud detection training
[2025-07-13T14:15:44.666+0000] {fraud_detection_training.py:120} INFO - Configuration loaded successfully
[2025-07-13T14:15:45.105+0000] {fraud_detection_training.py:164} INFO - Minio connection verified. Buckets: ['mlflow']
[2025-07-13T14:15:45.214+0000] {fraud_detection_training.py:314} INFO - Starting model training process
[2025-07-13T14:15:45.214+0000] {fraud_detection_training.py:189} INFO - Connecting to kafka topic transactions
[2025-07-13T14:15:45.215+0000] {logging_mixin.py:190} INFO - Kafka config - topic: %s, servers: %s, protocol: %s transactions ['broker:92092'] PLAINTEXT
[2025-07-13T14:15:45.217+0000] {conn.py:396} INFO - <BrokerConnection client_id=kafka-python-2.2.13, node_id=bootstrap-0 host=broker:92092 <connecting> [IPv4 ('172.18.0.10', 26556)]>: connecting to broker:92092 [('172.18.0.10', 26556) IPv4]
[2025-07-13T14:15:45.217+0000] {conn.py:429} ERROR - <BrokerConnection client_id=kafka-python-2.2.13, node_id=bootstrap-0 host=broker:92092 <connecting> [IPv4 ('172.18.0.10', 26556)]>: Connect attempt returned error 111. Disconnecting.
[2025-07-13T14:15:45.218+0000] {conn.py:945} ERROR - <BrokerConnection client_id=kafka-python-2.2.13, node_id=bootstrap-0 host=broker:92092 <connecting> [IPv4 ('172.18.0.10', 26556)]>: Closing connection. KafkaConnectionError: 111 ECONNREFUSED
[2025-07-13T14:15:45.218+0000] {client_async.py:1049} WARNING - No node available during check_version; sleeping 0.05 secs
[2025-07-13T14:15:45.273+0000] {conn.py:396} INFO - <BrokerConnection client_id=kafka-python-2.2.13, node_id=bootstrap-0 host=broker:92092 <connecting> [IPv4 ('172.18.0.10', 26556)]>: connecting to broker:92092 [('172.18.0.10', 26556) IPv4]
[2025-07-13T14:15:45.275+0000] {conn.py:429} ERROR - <BrokerConnection client_id=kafka-python-2.2.13, node_id=bootstrap-0 host=broker:92092 <connecting> [IPv4 ('172.18.0.10', 26556)]>: Connect attempt returned error 111. Disconnecting.
[2025-07-13T14:15:45.275+0000] {conn.py:945} ERROR - <BrokerConnection client_id=kafka-python-2.2.13, node_id=bootstrap-0 host=broker:92092 <connecting> [IPv4 ('172.18.0.10', 26556)]>: Closing connection. KafkaConnectionError: 111 ECONNREFUSED
[2025-07-13T14:15:45.276+0000] {client_async.py:1049} WARNING - No node available during check_version; sleeping 0.11 secs
[2025-07-13T14:15:45.385+0000] {conn.py:396} INFO - <BrokerConnection client_id=kafka-python-2.2.13, node_id=bootstrap-0 host=broker:92092 <connecting> [IPv4 ('172.18.0.10', 26556)]>: connecting to broker:92092 [('172.18.0.10', 26556) IPv4]
[2025-07-13T14:15:45.386+0000] {conn.py:429} ERROR - <BrokerConnection client_id=kafka-python-2.2.13, node_id=bootstrap-0 host=broker:92092 <connecting> [IPv4 ('172.18.0.10', 26556)]>: Connect attempt returned error 111. Disconnecting.
[2025-07-13T14:15:45.387+0000] {conn.py:945} ERROR - <BrokerConnection client_id=kafka-python-2.2.13, node_id=bootstrap-0 host=broker:92092 <connecting> [IPv4 ('172.18.0.10', 26556)]>: Closing connection. KafkaConnectionError: 111 ECONNREFUSED
[2025-07-13T14:15:45.387+0000] {client_async.py:1049} WARNING - No node available during check_version; sleeping 0.16 secs
[2025-07-13T14:15:45.549+0000] {conn.py:396} INFO - <BrokerConnection client_id=kafka-python-2.2.13, node_id=bootstrap-0 host=broker:92092 <connecting> [IPv4 ('172.18.0.10', 26556)]>: connecting to broker:92092 [('172.18.0.10', 26556) IPv4]
[2025-07-13T14:15:45.549+0000] {conn.py:429} ERROR - <BrokerConnection client_id=kafka-python-2.2.13, node_id=bootstrap-0 host=broker:92092 <connecting> [IPv4 ('172.18.0.10', 26556)]>: Connect attempt returned error 111. Disconnecting.
[2025-07-13T14:15:45.549+0000] {conn.py:945} ERROR - <BrokerConnection client_id=kafka-python-2.2.13, node_id=bootstrap-0 host=broker:92092 <connecting> [IPv4 ('172.18.0.10', 26556)]>: Closing connection. KafkaConnectionError: 111 ECONNREFUSED
[2025-07-13T14:15:45.550+0000] {client_async.py:1049} WARNING - No node available during check_version; sleeping 0.41 secs
[2025-07-13T14:15:45.956+0000] {conn.py:396} INFO - <BrokerConnection client_id=kafka-python-2.2.13, node_id=bootstrap-0 host=broker:92092 <connecting> [IPv4 ('172.18.0.10', 26556)]>: connecting to broker:92092 [('172.18.0.10', 26556) IPv4]
[2025-07-13T14:15:45.957+0000] {conn.py:429} ERROR - <BrokerConnection client_id=kafka-python-2.2.13, node_id=bootstrap-0 host=broker:92092 <connecting> [IPv4 ('172.18.0.10', 26556)]>: Connect attempt returned error 111. Disconnecting.
[2025-07-13T14:15:45.958+0000] {conn.py:945} ERROR - <BrokerConnection client_id=kafka-python-2.2.13, node_id=bootstrap-0 host=broker:92092 <connecting> [IPv4 ('172.18.0.10', 26556)]>: Closing connection. KafkaConnectionError: 111 ECONNREFUSED
[2025-07-13T14:15:45.958+0000] {client_async.py:1049} WARNING - No node available during check_version; sleeping 0.74 secs
[2025-07-13T14:15:46.701+0000] {conn.py:396} INFO - <BrokerConnection client_id=kafka-python-2.2.13, node_id=bootstrap-0 host=broker:92092 <connecting> [IPv4 ('172.18.0.10', 26556)]>: connecting to broker:92092 [('172.18.0.10', 26556) IPv4]
[2025-07-13T14:15:46.701+0000] {conn.py:429} ERROR - <BrokerConnection client_id=kafka-python-2.2.13, node_id=bootstrap-0 host=broker:92092 <connecting> [IPv4 ('172.18.0.10', 26556)]>: Connect attempt returned error 111. Disconnecting.
[2025-07-13T14:15:46.701+0000] {conn.py:945} ERROR - <BrokerConnection client_id=kafka-python-2.2.13, node_id=bootstrap-0 host=broker:92092 <connecting> [IPv4 ('172.18.0.10', 26556)]>: Closing connection. KafkaConnectionError: 111 ECONNREFUSED
[2025-07-13T14:15:46.702+0000] {client_async.py:1049} WARNING - No node available during check_version; sleeping 0.51 secs
[2025-07-13T14:15:47.216+0000] {fraud_detection_training.py:239} ERROR - Failed to read data from Kafka: NoBrokersAvailable
Traceback (most recent call last):
  File "/opt/airflow/dags/fraud_detection_training.py", line 211, in read_from_kafka
    consumer = KafkaConsumer(
               ^^^^^^^^^^^^^^
  File "/home/airflow/.local/lib/python3.12/site-packages/kafka/consumer/group.py", line 387, in __init__
    self._client = self.config['kafka_client'](metrics=self._metrics, **self.config)
                   ^^^^^^^^^^^^^^^^^^^^^^^^^^^^^^^^^^^^^^^^^^^^^^^^^^^^^^^^^^^^^^^^^
  File "/home/airflow/.local/lib/python3.12/site-packages/kafka/client_async.py", line 262, in __init__
    self.config['api_version'] = self.check_version()
                                 ^^^^^^^^^^^^^^^^^^^^
  File "/home/airflow/.local/lib/python3.12/site-packages/kafka/client_async.py", line 1074, in check_version
    raise Errors.NoBrokersAvailable()
kafka.errors.NoBrokersAvailable: NoBrokersAvailable
[2025-07-13T14:15:47.219+0000] {fraud_detection_training.py:475} ERROR - Training failed: NoBrokersAvailable
Traceback (most recent call last):
  File "/opt/airflow/dags/fraud_detection_training.py", line 317, in train_model
    df = self.read_from_kafka()
         ^^^^^^^^^^^^^^^^^^^^^^
  File "/opt/airflow/dags/fraud_detection_training.py", line 211, in read_from_kafka
    consumer = KafkaConsumer(
               ^^^^^^^^^^^^^^
  File "/home/airflow/.local/lib/python3.12/site-packages/kafka/consumer/group.py", line 387, in __init__
    self._client = self.config['kafka_client'](metrics=self._metrics, **self.config)
                   ^^^^^^^^^^^^^^^^^^^^^^^^^^^^^^^^^^^^^^^^^^^^^^^^^^^^^^^^^^^^^^^^^
  File "/home/airflow/.local/lib/python3.12/site-packages/kafka/client_async.py", line 262, in __init__
    self.config['api_version'] = self.check_version()
                                 ^^^^^^^^^^^^^^^^^^^^
  File "/home/airflow/.local/lib/python3.12/site-packages/kafka/client_async.py", line 1074, in check_version
    raise Errors.NoBrokersAvailable()
kafka.errors.NoBrokersAvailable: NoBrokersAvailable
[2025-07-13T14:15:47.221+0000] {fraud_detection_training_dag.py:29} ERROR - Training failed: NoBrokersAvailable
Traceback (most recent call last):
  File "/opt/airflow/dags/fraud_detection_training_dag.py", line 25, in _train_model
    model, precision = trainer.train_model()
                       ^^^^^^^^^^^^^^^^^^^^^
  File "/opt/airflow/dags/fraud_detection_training.py", line 317, in train_model
    df = self.read_from_kafka()
         ^^^^^^^^^^^^^^^^^^^^^^
  File "/opt/airflow/dags/fraud_detection_training.py", line 211, in read_from_kafka
    consumer = KafkaConsumer(
               ^^^^^^^^^^^^^^
  File "/home/airflow/.local/lib/python3.12/site-packages/kafka/consumer/group.py", line 387, in __init__
    self._client = self.config['kafka_client'](metrics=self._metrics, **self.config)
                   ^^^^^^^^^^^^^^^^^^^^^^^^^^^^^^^^^^^^^^^^^^^^^^^^^^^^^^^^^^^^^^^^^
  File "/home/airflow/.local/lib/python3.12/site-packages/kafka/client_async.py", line 262, in __init__
    self.config['api_version'] = self.check_version()
                                 ^^^^^^^^^^^^^^^^^^^^
  File "/home/airflow/.local/lib/python3.12/site-packages/kafka/client_async.py", line 1074, in check_version
    raise Errors.NoBrokersAvailable()
kafka.errors.NoBrokersAvailable: NoBrokersAvailable
[2025-07-13T14:15:47.232+0000] {taskinstance.py:3313} ERROR - Task failed with exception
Traceback (most recent call last):
  File "/opt/airflow/dags/fraud_detection_training_dag.py", line 25, in _train_model
    model, precision = trainer.train_model()
                       ^^^^^^^^^^^^^^^^^^^^^
  File "/opt/airflow/dags/fraud_detection_training.py", line 317, in train_model
    df = self.read_from_kafka()
         ^^^^^^^^^^^^^^^^^^^^^^
  File "/opt/airflow/dags/fraud_detection_training.py", line 211, in read_from_kafka
    consumer = KafkaConsumer(
               ^^^^^^^^^^^^^^
  File "/home/airflow/.local/lib/python3.12/site-packages/kafka/consumer/group.py", line 387, in __init__
    self._client = self.config['kafka_client'](metrics=self._metrics, **self.config)
                   ^^^^^^^^^^^^^^^^^^^^^^^^^^^^^^^^^^^^^^^^^^^^^^^^^^^^^^^^^^^^^^^^^
  File "/home/airflow/.local/lib/python3.12/site-packages/kafka/client_async.py", line 262, in __init__
    self.config['api_version'] = self.check_version()
                                 ^^^^^^^^^^^^^^^^^^^^
  File "/home/airflow/.local/lib/python3.12/site-packages/kafka/client_async.py", line 1074, in check_version
    raise Errors.NoBrokersAvailable()
kafka.errors.NoBrokersAvailable: NoBrokersAvailable

During handling of the above exception, another exception occurred:

Traceback (most recent call last):
  File "/home/airflow/.local/lib/python3.12/site-packages/airflow/models/taskinstance.py", line 768, in _execute_task
    result = _execute_callable(context=context, **execute_callable_kwargs)
             ^^^^^^^^^^^^^^^^^^^^^^^^^^^^^^^^^^^^^^^^^^^^^^^^^^^^^^^^^^^^^
  File "/home/airflow/.local/lib/python3.12/site-packages/airflow/models/taskinstance.py", line 734, in _execute_callable
    return ExecutionCallableRunner(
           ^^^^^^^^^^^^^^^^^^^^^^^^
  File "/home/airflow/.local/lib/python3.12/site-packages/airflow/utils/operator_helpers.py", line 252, in run
    return self.func(*args, **kwargs)
           ^^^^^^^^^^^^^^^^^^^^^^^^^^
  File "/home/airflow/.local/lib/python3.12/site-packages/airflow/models/baseoperator.py", line 424, in wrapper
    return func(self, *args, **kwargs)
           ^^^^^^^^^^^^^^^^^^^^^^^^^^^
  File "/home/airflow/.local/lib/python3.12/site-packages/airflow/operators/python.py", line 238, in execute
    return_value = self.execute_callable()
                   ^^^^^^^^^^^^^^^^^^^^^^^
  File "/home/airflow/.local/lib/python3.12/site-packages/airflow/operators/python.py", line 256, in execute_callable
    return runner.run(*self.op_args, **self.op_kwargs)
           ^^^^^^^^^^^^^^^^^^^^^^^^^^^^^^^^^^^^^^^^^^^
  File "/home/airflow/.local/lib/python3.12/site-packages/airflow/utils/operator_helpers.py", line 252, in run
    return self.func(*args, **kwargs)
           ^^^^^^^^^^^^^^^^^^^^^^^^^^
  File "/opt/airflow/dags/fraud_detection_training_dag.py", line 30, in _train_model
    raise AirflowException(f'Model training failed: {str(e)}')
airflow.exceptions.AirflowException: Model training failed: NoBrokersAvailable
[2025-07-13T14:15:47.237+0000] {taskinstance.py:1226} INFO - Marking task as FAILED. dag_id=fraud_detection_training, task_id=execute_training, run_id=manual__2025-07-13T14:15:38.902575+00:00, execution_date=20250713T141538, start_date=20250713T141540, end_date=20250713T141547
[2025-07-13T14:15:47.274+0000] {taskinstance.py:341} INFO - ::group::Post task execution logs
[2025-07-13T14:15:47.275+0000] {standard_task_runner.py:124} ERROR - Failed to execute job 34 for task execute_training (Model training failed: NoBrokersAvailable; 2763)
Traceback (most recent call last):
  File "/opt/airflow/dags/fraud_detection_training_dag.py", line 25, in _train_model
    model, precision = trainer.train_model()
                       ^^^^^^^^^^^^^^^^^^^^^
  File "/opt/airflow/dags/fraud_detection_training.py", line 317, in train_model
    df = self.read_from_kafka()
         ^^^^^^^^^^^^^^^^^^^^^^
  File "/opt/airflow/dags/fraud_detection_training.py", line 211, in read_from_kafka
    consumer = KafkaConsumer(
               ^^^^^^^^^^^^^^
  File "/home/airflow/.local/lib/python3.12/site-packages/kafka/consumer/group.py", line 387, in __init__
    self._client = self.config['kafka_client'](metrics=self._metrics, **self.config)
                   ^^^^^^^^^^^^^^^^^^^^^^^^^^^^^^^^^^^^^^^^^^^^^^^^^^^^^^^^^^^^^^^^^
  File "/home/airflow/.local/lib/python3.12/site-packages/kafka/client_async.py", line 262, in __init__
    self.config['api_version'] = self.check_version()
                                 ^^^^^^^^^^^^^^^^^^^^
  File "/home/airflow/.local/lib/python3.12/site-packages/kafka/client_async.py", line 1074, in check_version
    raise Errors.NoBrokersAvailable()
kafka.errors.NoBrokersAvailable: NoBrokersAvailable

During handling of the above exception, another exception occurred:

Traceback (most recent call last):
  File "/home/airflow/.local/lib/python3.12/site-packages/airflow/task/task_runner/standard_task_runner.py", line 117, in _start_by_fork
    ret = args.func(args, dag=self.dag)
          ^^^^^^^^^^^^^^^^^^^^^^^^^^^^^
  File "/home/airflow/.local/lib/python3.12/site-packages/airflow/cli/cli_config.py", line 49, in command
    return func(*args, **kwargs)
           ^^^^^^^^^^^^^^^^^^^^^
  File "/home/airflow/.local/lib/python3.12/site-packages/airflow/utils/cli.py", line 116, in wrapper
    return f(*args, **kwargs)
           ^^^^^^^^^^^^^^^^^^
  File "/home/airflow/.local/lib/python3.12/site-packages/airflow/cli/commands/task_command.py", line 483, in task_run
    task_return_code = _run_task_by_selected_method(args, _dag, ti)
                       ^^^^^^^^^^^^^^^^^^^^^^^^^^^^^^^^^^^^^^^^^^^^
  File "/home/airflow/.local/lib/python3.12/site-packages/airflow/cli/commands/task_command.py", line 256, in _run_task_by_selected_method
    return _run_raw_task(args, ti)
           ^^^^^^^^^^^^^^^^^^^^^^^
  File "/home/airflow/.local/lib/python3.12/site-packages/airflow/cli/commands/task_command.py", line 341, in _run_raw_task
    return ti._run_raw_task(
           ^^^^^^^^^^^^^^^^^
  File "/home/airflow/.local/lib/python3.12/site-packages/airflow/utils/session.py", line 97, in wrapper
    return func(*args, session=session, **kwargs)
           ^^^^^^^^^^^^^^^^^^^^^^^^^^^^^^^^^^^^^^
  File "/home/airflow/.local/lib/python3.12/site-packages/airflow/models/taskinstance.py", line 3006, in _run_raw_task
    return _run_raw_task(
           ^^^^^^^^^^^^^^
  File "/home/airflow/.local/lib/python3.12/site-packages/airflow/models/taskinstance.py", line 274, in _run_raw_task
    TaskInstance._execute_task_with_callbacks(
  File "/home/airflow/.local/lib/python3.12/site-packages/airflow/models/taskinstance.py", line 3161, in _execute_task_with_callbacks
    result = self._execute_task(context, task_orig)
             ^^^^^^^^^^^^^^^^^^^^^^^^^^^^^^^^^^^^^^
  File "/home/airflow/.local/lib/python3.12/site-packages/airflow/models/taskinstance.py", line 3185, in _execute_task
    return _execute_task(self, context, task_orig)
           ^^^^^^^^^^^^^^^^^^^^^^^^^^^^^^^^^^^^^^^
  File "/home/airflow/.local/lib/python3.12/site-packages/airflow/models/taskinstance.py", line 768, in _execute_task
    result = _execute_callable(context=context, **execute_callable_kwargs)
             ^^^^^^^^^^^^^^^^^^^^^^^^^^^^^^^^^^^^^^^^^^^^^^^^^^^^^^^^^^^^^
  File "/home/airflow/.local/lib/python3.12/site-packages/airflow/models/taskinstance.py", line 734, in _execute_callable
    return ExecutionCallableRunner(
           ^^^^^^^^^^^^^^^^^^^^^^^^
  File "/home/airflow/.local/lib/python3.12/site-packages/airflow/utils/operator_helpers.py", line 252, in run
    return self.func(*args, **kwargs)
           ^^^^^^^^^^^^^^^^^^^^^^^^^^
  File "/home/airflow/.local/lib/python3.12/site-packages/airflow/models/baseoperator.py", line 424, in wrapper
    return func(self, *args, **kwargs)
           ^^^^^^^^^^^^^^^^^^^^^^^^^^^
  File "/home/airflow/.local/lib/python3.12/site-packages/airflow/operators/python.py", line 238, in execute
    return_value = self.execute_callable()
                   ^^^^^^^^^^^^^^^^^^^^^^^
  File "/home/airflow/.local/lib/python3.12/site-packages/airflow/operators/python.py", line 256, in execute_callable
    return runner.run(*self.op_args, **self.op_kwargs)
           ^^^^^^^^^^^^^^^^^^^^^^^^^^^^^^^^^^^^^^^^^^^
  File "/home/airflow/.local/lib/python3.12/site-packages/airflow/utils/operator_helpers.py", line 252, in run
    return self.func(*args, **kwargs)
           ^^^^^^^^^^^^^^^^^^^^^^^^^^
  File "/opt/airflow/dags/fraud_detection_training_dag.py", line 30, in _train_model
    raise AirflowException(f'Model training failed: {str(e)}')
airflow.exceptions.AirflowException: Model training failed: NoBrokersAvailable
[2025-07-13T14:15:47.320+0000] {local_task_job_runner.py:266} INFO - Task exited with return code 1
[2025-07-13T14:15:47.347+0000] {taskinstance.py:3901} INFO - 1 downstream tasks scheduled from follow-on schedule check
[2025-07-13T14:15:47.348+0000] {local_task_job_runner.py:245} INFO - ::endgroup::
