[2025-07-13T14:14:27.824+0000] {local_task_job_runner.py:123} INFO - ::group::Pre task execution logs
[2025-07-13T14:14:27.850+0000] {taskinstance.py:2614} INFO - Dependencies all met for dep_context=non-requeueable deps ti=<TaskInstance: fraud_detection_training.execute_training manual__2025-07-13T14:14:25.865641+00:00 [queued]>
[2025-07-13T14:14:27.862+0000] {taskinstance.py:2614} INFO - Dependencies all met for dep_context=requeueable deps ti=<TaskInstance: fraud_detection_training.execute_training manual__2025-07-13T14:14:25.865641+00:00 [queued]>
[2025-07-13T14:14:27.862+0000] {taskinstance.py:2867} INFO - Starting attempt 1 of 1
[2025-07-13T14:14:27.880+0000] {taskinstance.py:2890} INFO - Executing <Task(PythonOperator): execute_training> on 2025-07-13 14:14:25.865641+00:00
[2025-07-13T14:14:27.888+0000] {warnings.py:112} WARNING - /home/***/.local/lib/python3.12/site-packages/***/task/task_runner/standard_task_runner.py:70: DeprecationWarning: This process (pid=2776) is multi-threaded, use of fork() may lead to deadlocks in the child.
  pid = os.fork()

[2025-07-13T14:14:27.890+0000] {standard_task_runner.py:72} INFO - Started process 2777 to run task
[2025-07-13T14:14:27.890+0000] {standard_task_runner.py:104} INFO - Running: ['***', 'tasks', 'run', 'fraud_detection_training', 'execute_training', 'manual__2025-07-13T14:14:25.865641+00:00', '--job-id', '31', '--raw', '--subdir', 'DAGS_FOLDER/fraud_detection_training_dag.py', '--cfg-path', '/tmp/tmpl9pyz6ri']
[2025-07-13T14:14:27.892+0000] {standard_task_runner.py:105} INFO - Job 31: Subtask execute_training
[2025-07-13T14:14:27.942+0000] {task_command.py:467} INFO - Running <TaskInstance: fraud_detection_training.execute_training manual__2025-07-13T14:14:25.865641+00:00 [running]> on host 93c736137477
[2025-07-13T14:14:28.041+0000] {taskinstance.py:3134} INFO - Exporting env vars: AIRFLOW_CTX_DAG_OWNER='datamasterylab.com' AIRFLOW_CTX_DAG_ID='fraud_detection_training' AIRFLOW_CTX_TASK_ID='execute_training' AIRFLOW_CTX_EXECUTION_DATE='2025-07-13T14:14:25.865641+00:00' AIRFLOW_CTX_TRY_NUMBER='1' AIRFLOW_CTX_DAG_RUN_ID='manual__2025-07-13T14:14:25.865641+00:00'
[2025-07-13T14:14:28.041+0000] {taskinstance.py:732} INFO - ::endgroup::
[2025-07-13T14:14:31.716+0000] {warnings.py:112} WARNING - /opt/***/dags/fraud_detection_training.py:45: UserWarning: The numpy.array_api submodule is still experimental. See NEP 47.
  from numpy.array_api import astype

[2025-07-13T14:14:31.758+0000] {fraud_detection_training_dag.py:23} INFO - Initializing fraud detection training
[2025-07-13T14:14:31.766+0000] {fraud_detection_training.py:120} INFO - Configuration loaded successfully
[2025-07-13T14:14:32.202+0000] {fraud_detection_training.py:164} INFO - Minio connection verified. Buckets: ['mlflow']
[2025-07-13T14:14:32.308+0000] {fraud_detection_training.py:314} INFO - Starting model training process
[2025-07-13T14:14:32.309+0000] {fraud_detection_training.py:189} INFO - Connecting to kafka topic transactions
[2025-07-13T14:14:32.310+0000] {logging_mixin.py:190} INFO - Kafka config - topic: %s, servers: %s, protocol: %s transactions ['localhost:9092'] PLAINTEXT
[2025-07-13T14:14:32.312+0000] {conn.py:396} INFO - <BrokerConnection client_id=kafka-python-2.2.13, node_id=bootstrap-0 host=localhost:9092 <connecting> [IPv6 ('::1', 9092, 0, 0)]>: connecting to localhost:9092 [('::1', 9092, 0, 0) IPv6]
[2025-07-13T14:14:32.312+0000] {conn.py:429} ERROR - <BrokerConnection client_id=kafka-python-2.2.13, node_id=bootstrap-0 host=localhost:9092 <connecting> [IPv6 ('::1', 9092, 0, 0)]>: Connect attempt returned error 111. Disconnecting.
[2025-07-13T14:14:32.313+0000] {conn.py:945} ERROR - <BrokerConnection client_id=kafka-python-2.2.13, node_id=bootstrap-0 host=localhost:9092 <connecting> [IPv6 ('::1', 9092, 0, 0)]>: Closing connection. KafkaConnectionError: 111 ECONNREFUSED
[2025-07-13T14:14:32.313+0000] {conn.py:396} INFO - <BrokerConnection client_id=kafka-python-2.2.13, node_id=bootstrap-0 host=localhost:9092 <connecting> [IPv4 ('127.0.0.1', 9092)]>: connecting to localhost:9092 [('127.0.0.1', 9092) IPv4]
[2025-07-13T14:14:32.314+0000] {conn.py:429} ERROR - <BrokerConnection client_id=kafka-python-2.2.13, node_id=bootstrap-0 host=localhost:9092 <connecting> [IPv4 ('127.0.0.1', 9092)]>: Connect attempt returned error 111. Disconnecting.
[2025-07-13T14:14:32.314+0000] {conn.py:945} ERROR - <BrokerConnection client_id=kafka-python-2.2.13, node_id=bootstrap-0 host=localhost:9092 <connecting> [IPv4 ('127.0.0.1', 9092)]>: Closing connection. KafkaConnectionError: 111 ECONNREFUSED
[2025-07-13T14:14:32.315+0000] {client_async.py:1049} WARNING - No node available during check_version; sleeping 0.05 secs
[2025-07-13T14:14:32.370+0000] {conn.py:396} INFO - <BrokerConnection client_id=kafka-python-2.2.13, node_id=bootstrap-0 host=localhost:9092 <connecting> [IPv6 ('::1', 9092, 0, 0)]>: connecting to localhost:9092 [('::1', 9092, 0, 0) IPv6]
[2025-07-13T14:14:32.371+0000] {conn.py:429} ERROR - <BrokerConnection client_id=kafka-python-2.2.13, node_id=bootstrap-0 host=localhost:9092 <connecting> [IPv6 ('::1', 9092, 0, 0)]>: Connect attempt returned error 111. Disconnecting.
[2025-07-13T14:14:32.371+0000] {conn.py:945} ERROR - <BrokerConnection client_id=kafka-python-2.2.13, node_id=bootstrap-0 host=localhost:9092 <connecting> [IPv6 ('::1', 9092, 0, 0)]>: Closing connection. KafkaConnectionError: 111 ECONNREFUSED
[2025-07-13T14:14:32.372+0000] {conn.py:396} INFO - <BrokerConnection client_id=kafka-python-2.2.13, node_id=bootstrap-0 host=localhost:9092 <connecting> [IPv4 ('127.0.0.1', 9092)]>: connecting to localhost:9092 [('127.0.0.1', 9092) IPv4]
[2025-07-13T14:14:32.372+0000] {conn.py:429} ERROR - <BrokerConnection client_id=kafka-python-2.2.13, node_id=bootstrap-0 host=localhost:9092 <connecting> [IPv4 ('127.0.0.1', 9092)]>: Connect attempt returned error 111. Disconnecting.
[2025-07-13T14:14:32.372+0000] {conn.py:945} ERROR - <BrokerConnection client_id=kafka-python-2.2.13, node_id=bootstrap-0 host=localhost:9092 <connecting> [IPv4 ('127.0.0.1', 9092)]>: Closing connection. KafkaConnectionError: 111 ECONNREFUSED
[2025-07-13T14:14:32.373+0000] {client_async.py:1049} WARNING - No node available during check_version; sleeping 0.10 secs
[2025-07-13T14:14:32.476+0000] {conn.py:396} INFO - <BrokerConnection client_id=kafka-python-2.2.13, node_id=bootstrap-0 host=localhost:9092 <connecting> [IPv6 ('::1', 9092, 0, 0)]>: connecting to localhost:9092 [('::1', 9092, 0, 0) IPv6]
[2025-07-13T14:14:32.477+0000] {conn.py:429} ERROR - <BrokerConnection client_id=kafka-python-2.2.13, node_id=bootstrap-0 host=localhost:9092 <connecting> [IPv6 ('::1', 9092, 0, 0)]>: Connect attempt returned error 111. Disconnecting.
[2025-07-13T14:14:32.477+0000] {conn.py:945} ERROR - <BrokerConnection client_id=kafka-python-2.2.13, node_id=bootstrap-0 host=localhost:9092 <connecting> [IPv6 ('::1', 9092, 0, 0)]>: Closing connection. KafkaConnectionError: 111 ECONNREFUSED
[2025-07-13T14:14:32.478+0000] {conn.py:396} INFO - <BrokerConnection client_id=kafka-python-2.2.13, node_id=bootstrap-0 host=localhost:9092 <connecting> [IPv4 ('127.0.0.1', 9092)]>: connecting to localhost:9092 [('127.0.0.1', 9092) IPv4]
[2025-07-13T14:14:32.479+0000] {conn.py:429} ERROR - <BrokerConnection client_id=kafka-python-2.2.13, node_id=bootstrap-0 host=localhost:9092 <connecting> [IPv4 ('127.0.0.1', 9092)]>: Connect attempt returned error 111. Disconnecting.
[2025-07-13T14:14:32.479+0000] {conn.py:945} ERROR - <BrokerConnection client_id=kafka-python-2.2.13, node_id=bootstrap-0 host=localhost:9092 <connecting> [IPv4 ('127.0.0.1', 9092)]>: Closing connection. KafkaConnectionError: 111 ECONNREFUSED
[2025-07-13T14:14:32.480+0000] {client_async.py:1049} WARNING - No node available during check_version; sleeping 0.19 secs
[2025-07-13T14:14:32.670+0000] {conn.py:396} INFO - <BrokerConnection client_id=kafka-python-2.2.13, node_id=bootstrap-0 host=localhost:9092 <connecting> [IPv6 ('::1', 9092, 0, 0)]>: connecting to localhost:9092 [('::1', 9092, 0, 0) IPv6]
[2025-07-13T14:14:32.670+0000] {conn.py:429} ERROR - <BrokerConnection client_id=kafka-python-2.2.13, node_id=bootstrap-0 host=localhost:9092 <connecting> [IPv6 ('::1', 9092, 0, 0)]>: Connect attempt returned error 111. Disconnecting.
[2025-07-13T14:14:32.670+0000] {conn.py:945} ERROR - <BrokerConnection client_id=kafka-python-2.2.13, node_id=bootstrap-0 host=localhost:9092 <connecting> [IPv6 ('::1', 9092, 0, 0)]>: Closing connection. KafkaConnectionError: 111 ECONNREFUSED
[2025-07-13T14:14:32.671+0000] {conn.py:396} INFO - <BrokerConnection client_id=kafka-python-2.2.13, node_id=bootstrap-0 host=localhost:9092 <connecting> [IPv4 ('127.0.0.1', 9092)]>: connecting to localhost:9092 [('127.0.0.1', 9092) IPv4]
[2025-07-13T14:14:32.671+0000] {conn.py:429} ERROR - <BrokerConnection client_id=kafka-python-2.2.13, node_id=bootstrap-0 host=localhost:9092 <connecting> [IPv4 ('127.0.0.1', 9092)]>: Connect attempt returned error 111. Disconnecting.
[2025-07-13T14:14:32.671+0000] {conn.py:945} ERROR - <BrokerConnection client_id=kafka-python-2.2.13, node_id=bootstrap-0 host=localhost:9092 <connecting> [IPv4 ('127.0.0.1', 9092)]>: Closing connection. KafkaConnectionError: 111 ECONNREFUSED
[2025-07-13T14:14:32.672+0000] {client_async.py:1049} WARNING - No node available during check_version; sleeping 0.42 secs
[2025-07-13T14:14:33.094+0000] {conn.py:396} INFO - <BrokerConnection client_id=kafka-python-2.2.13, node_id=bootstrap-0 host=localhost:9092 <connecting> [IPv6 ('::1', 9092, 0, 0)]>: connecting to localhost:9092 [('::1', 9092, 0, 0) IPv6]
[2025-07-13T14:14:33.095+0000] {conn.py:429} ERROR - <BrokerConnection client_id=kafka-python-2.2.13, node_id=bootstrap-0 host=localhost:9092 <connecting> [IPv6 ('::1', 9092, 0, 0)]>: Connect attempt returned error 111. Disconnecting.
[2025-07-13T14:14:33.095+0000] {conn.py:945} ERROR - <BrokerConnection client_id=kafka-python-2.2.13, node_id=bootstrap-0 host=localhost:9092 <connecting> [IPv6 ('::1', 9092, 0, 0)]>: Closing connection. KafkaConnectionError: 111 ECONNREFUSED
[2025-07-13T14:14:33.096+0000] {conn.py:396} INFO - <BrokerConnection client_id=kafka-python-2.2.13, node_id=bootstrap-0 host=localhost:9092 <connecting> [IPv4 ('127.0.0.1', 9092)]>: connecting to localhost:9092 [('127.0.0.1', 9092) IPv4]
[2025-07-13T14:14:33.096+0000] {conn.py:429} ERROR - <BrokerConnection client_id=kafka-python-2.2.13, node_id=bootstrap-0 host=localhost:9092 <connecting> [IPv4 ('127.0.0.1', 9092)]>: Connect attempt returned error 111. Disconnecting.
[2025-07-13T14:14:33.096+0000] {conn.py:945} ERROR - <BrokerConnection client_id=kafka-python-2.2.13, node_id=bootstrap-0 host=localhost:9092 <connecting> [IPv4 ('127.0.0.1', 9092)]>: Closing connection. KafkaConnectionError: 111 ECONNREFUSED
[2025-07-13T14:14:33.097+0000] {client_async.py:1049} WARNING - No node available during check_version; sleeping 0.70 secs
[2025-07-13T14:14:33.797+0000] {conn.py:396} INFO - <BrokerConnection client_id=kafka-python-2.2.13, node_id=bootstrap-0 host=localhost:9092 <connecting> [IPv6 ('::1', 9092, 0, 0)]>: connecting to localhost:9092 [('::1', 9092, 0, 0) IPv6]
[2025-07-13T14:14:33.798+0000] {conn.py:429} ERROR - <BrokerConnection client_id=kafka-python-2.2.13, node_id=bootstrap-0 host=localhost:9092 <connecting> [IPv6 ('::1', 9092, 0, 0)]>: Connect attempt returned error 111. Disconnecting.
[2025-07-13T14:14:33.799+0000] {conn.py:945} ERROR - <BrokerConnection client_id=kafka-python-2.2.13, node_id=bootstrap-0 host=localhost:9092 <connecting> [IPv6 ('::1', 9092, 0, 0)]>: Closing connection. KafkaConnectionError: 111 ECONNREFUSED
[2025-07-13T14:14:33.799+0000] {conn.py:396} INFO - <BrokerConnection client_id=kafka-python-2.2.13, node_id=bootstrap-0 host=localhost:9092 <connecting> [IPv4 ('127.0.0.1', 9092)]>: connecting to localhost:9092 [('127.0.0.1', 9092) IPv4]
[2025-07-13T14:14:33.800+0000] {conn.py:429} ERROR - <BrokerConnection client_id=kafka-python-2.2.13, node_id=bootstrap-0 host=localhost:9092 <connecting> [IPv4 ('127.0.0.1', 9092)]>: Connect attempt returned error 111. Disconnecting.
[2025-07-13T14:14:33.800+0000] {conn.py:945} ERROR - <BrokerConnection client_id=kafka-python-2.2.13, node_id=bootstrap-0 host=localhost:9092 <connecting> [IPv4 ('127.0.0.1', 9092)]>: Closing connection. KafkaConnectionError: 111 ECONNREFUSED
[2025-07-13T14:14:33.801+0000] {client_async.py:1049} WARNING - No node available during check_version; sleeping 0.51 secs
[2025-07-13T14:14:34.311+0000] {fraud_detection_training.py:239} ERROR - Failed to read data from Kafka: NoBrokersAvailable
Traceback (most recent call last):
  File "/opt/airflow/dags/fraud_detection_training.py", line 211, in read_from_kafka
    consumer = KafkaConsumer(
               ^^^^^^^^^^^^^^
  File "/home/airflow/.local/lib/python3.12/site-packages/kafka/consumer/group.py", line 387, in __init__
    self._client = self.config['kafka_client'](metrics=self._metrics, **self.config)
                   ^^^^^^^^^^^^^^^^^^^^^^^^^^^^^^^^^^^^^^^^^^^^^^^^^^^^^^^^^^^^^^^^^
  File "/home/airflow/.local/lib/python3.12/site-packages/kafka/client_async.py", line 262, in __init__
    self.config['api_version'] = self.check_version()
                                 ^^^^^^^^^^^^^^^^^^^^
  File "/home/airflow/.local/lib/python3.12/site-packages/kafka/client_async.py", line 1074, in check_version
    raise Errors.NoBrokersAvailable()
kafka.errors.NoBrokersAvailable: NoBrokersAvailable
[2025-07-13T14:14:34.324+0000] {fraud_detection_training.py:475} ERROR - Training failed: NoBrokersAvailable
Traceback (most recent call last):
  File "/opt/airflow/dags/fraud_detection_training.py", line 317, in train_model
    df = self.read_from_kafka()
         ^^^^^^^^^^^^^^^^^^^^^^
  File "/opt/airflow/dags/fraud_detection_training.py", line 211, in read_from_kafka
    consumer = KafkaConsumer(
               ^^^^^^^^^^^^^^
  File "/home/airflow/.local/lib/python3.12/site-packages/kafka/consumer/group.py", line 387, in __init__
    self._client = self.config['kafka_client'](metrics=self._metrics, **self.config)
                   ^^^^^^^^^^^^^^^^^^^^^^^^^^^^^^^^^^^^^^^^^^^^^^^^^^^^^^^^^^^^^^^^^
  File "/home/airflow/.local/lib/python3.12/site-packages/kafka/client_async.py", line 262, in __init__
    self.config['api_version'] = self.check_version()
                                 ^^^^^^^^^^^^^^^^^^^^
  File "/home/airflow/.local/lib/python3.12/site-packages/kafka/client_async.py", line 1074, in check_version
    raise Errors.NoBrokersAvailable()
kafka.errors.NoBrokersAvailable: NoBrokersAvailable
[2025-07-13T14:14:34.325+0000] {fraud_detection_training_dag.py:29} ERROR - Training failed: NoBrokersAvailable
Traceback (most recent call last):
  File "/opt/airflow/dags/fraud_detection_training_dag.py", line 25, in _train_model
    model, precision = trainer.train_model()
                       ^^^^^^^^^^^^^^^^^^^^^
  File "/opt/airflow/dags/fraud_detection_training.py", line 317, in train_model
    df = self.read_from_kafka()
         ^^^^^^^^^^^^^^^^^^^^^^
  File "/opt/airflow/dags/fraud_detection_training.py", line 211, in read_from_kafka
    consumer = KafkaConsumer(
               ^^^^^^^^^^^^^^
  File "/home/airflow/.local/lib/python3.12/site-packages/kafka/consumer/group.py", line 387, in __init__
    self._client = self.config['kafka_client'](metrics=self._metrics, **self.config)
                   ^^^^^^^^^^^^^^^^^^^^^^^^^^^^^^^^^^^^^^^^^^^^^^^^^^^^^^^^^^^^^^^^^
  File "/home/airflow/.local/lib/python3.12/site-packages/kafka/client_async.py", line 262, in __init__
    self.config['api_version'] = self.check_version()
                                 ^^^^^^^^^^^^^^^^^^^^
  File "/home/airflow/.local/lib/python3.12/site-packages/kafka/client_async.py", line 1074, in check_version
    raise Errors.NoBrokersAvailable()
kafka.errors.NoBrokersAvailable: NoBrokersAvailable
[2025-07-13T14:14:34.337+0000] {taskinstance.py:3313} ERROR - Task failed with exception
Traceback (most recent call last):
  File "/opt/airflow/dags/fraud_detection_training_dag.py", line 25, in _train_model
    model, precision = trainer.train_model()
                       ^^^^^^^^^^^^^^^^^^^^^
  File "/opt/airflow/dags/fraud_detection_training.py", line 317, in train_model
    df = self.read_from_kafka()
         ^^^^^^^^^^^^^^^^^^^^^^
  File "/opt/airflow/dags/fraud_detection_training.py", line 211, in read_from_kafka
    consumer = KafkaConsumer(
               ^^^^^^^^^^^^^^
  File "/home/airflow/.local/lib/python3.12/site-packages/kafka/consumer/group.py", line 387, in __init__
    self._client = self.config['kafka_client'](metrics=self._metrics, **self.config)
                   ^^^^^^^^^^^^^^^^^^^^^^^^^^^^^^^^^^^^^^^^^^^^^^^^^^^^^^^^^^^^^^^^^
  File "/home/airflow/.local/lib/python3.12/site-packages/kafka/client_async.py", line 262, in __init__
    self.config['api_version'] = self.check_version()
                                 ^^^^^^^^^^^^^^^^^^^^
  File "/home/airflow/.local/lib/python3.12/site-packages/kafka/client_async.py", line 1074, in check_version
    raise Errors.NoBrokersAvailable()
kafka.errors.NoBrokersAvailable: NoBrokersAvailable

During handling of the above exception, another exception occurred:

Traceback (most recent call last):
  File "/home/airflow/.local/lib/python3.12/site-packages/airflow/models/taskinstance.py", line 768, in _execute_task
    result = _execute_callable(context=context, **execute_callable_kwargs)
             ^^^^^^^^^^^^^^^^^^^^^^^^^^^^^^^^^^^^^^^^^^^^^^^^^^^^^^^^^^^^^
  File "/home/airflow/.local/lib/python3.12/site-packages/airflow/models/taskinstance.py", line 734, in _execute_callable
    return ExecutionCallableRunner(
           ^^^^^^^^^^^^^^^^^^^^^^^^
  File "/home/airflow/.local/lib/python3.12/site-packages/airflow/utils/operator_helpers.py", line 252, in run
    return self.func(*args, **kwargs)
           ^^^^^^^^^^^^^^^^^^^^^^^^^^
  File "/home/airflow/.local/lib/python3.12/site-packages/airflow/models/baseoperator.py", line 424, in wrapper
    return func(self, *args, **kwargs)
           ^^^^^^^^^^^^^^^^^^^^^^^^^^^
  File "/home/airflow/.local/lib/python3.12/site-packages/airflow/operators/python.py", line 238, in execute
    return_value = self.execute_callable()
                   ^^^^^^^^^^^^^^^^^^^^^^^
  File "/home/airflow/.local/lib/python3.12/site-packages/airflow/operators/python.py", line 256, in execute_callable
    return runner.run(*self.op_args, **self.op_kwargs)
           ^^^^^^^^^^^^^^^^^^^^^^^^^^^^^^^^^^^^^^^^^^^
  File "/home/airflow/.local/lib/python3.12/site-packages/airflow/utils/operator_helpers.py", line 252, in run
    return self.func(*args, **kwargs)
           ^^^^^^^^^^^^^^^^^^^^^^^^^^
  File "/opt/airflow/dags/fraud_detection_training_dag.py", line 30, in _train_model
    raise AirflowException(f'Model training failed: {str(e)}')
airflow.exceptions.AirflowException: Model training failed: NoBrokersAvailable
[2025-07-13T14:14:34.344+0000] {taskinstance.py:1226} INFO - Marking task as FAILED. dag_id=fraud_detection_training, task_id=execute_training, run_id=manual__2025-07-13T14:14:25.865641+00:00, execution_date=20250713T141425, start_date=20250713T141427, end_date=20250713T141434
[2025-07-13T14:14:34.370+0000] {taskinstance.py:341} INFO - ::group::Post task execution logs
[2025-07-13T14:14:34.371+0000] {standard_task_runner.py:124} ERROR - Failed to execute job 31 for task execute_training (Model training failed: NoBrokersAvailable; 2777)
Traceback (most recent call last):
  File "/opt/airflow/dags/fraud_detection_training_dag.py", line 25, in _train_model
    model, precision = trainer.train_model()
                       ^^^^^^^^^^^^^^^^^^^^^
  File "/opt/airflow/dags/fraud_detection_training.py", line 317, in train_model
    df = self.read_from_kafka()
         ^^^^^^^^^^^^^^^^^^^^^^
  File "/opt/airflow/dags/fraud_detection_training.py", line 211, in read_from_kafka
    consumer = KafkaConsumer(
               ^^^^^^^^^^^^^^
  File "/home/airflow/.local/lib/python3.12/site-packages/kafka/consumer/group.py", line 387, in __init__
    self._client = self.config['kafka_client'](metrics=self._metrics, **self.config)
                   ^^^^^^^^^^^^^^^^^^^^^^^^^^^^^^^^^^^^^^^^^^^^^^^^^^^^^^^^^^^^^^^^^
  File "/home/airflow/.local/lib/python3.12/site-packages/kafka/client_async.py", line 262, in __init__
    self.config['api_version'] = self.check_version()
                                 ^^^^^^^^^^^^^^^^^^^^
  File "/home/airflow/.local/lib/python3.12/site-packages/kafka/client_async.py", line 1074, in check_version
    raise Errors.NoBrokersAvailable()
kafka.errors.NoBrokersAvailable: NoBrokersAvailable

During handling of the above exception, another exception occurred:

Traceback (most recent call last):
  File "/home/airflow/.local/lib/python3.12/site-packages/airflow/task/task_runner/standard_task_runner.py", line 117, in _start_by_fork
    ret = args.func(args, dag=self.dag)
          ^^^^^^^^^^^^^^^^^^^^^^^^^^^^^
  File "/home/airflow/.local/lib/python3.12/site-packages/airflow/cli/cli_config.py", line 49, in command
    return func(*args, **kwargs)
           ^^^^^^^^^^^^^^^^^^^^^
  File "/home/airflow/.local/lib/python3.12/site-packages/airflow/utils/cli.py", line 116, in wrapper
    return f(*args, **kwargs)
           ^^^^^^^^^^^^^^^^^^
  File "/home/airflow/.local/lib/python3.12/site-packages/airflow/cli/commands/task_command.py", line 483, in task_run
    task_return_code = _run_task_by_selected_method(args, _dag, ti)
                       ^^^^^^^^^^^^^^^^^^^^^^^^^^^^^^^^^^^^^^^^^^^^
  File "/home/airflow/.local/lib/python3.12/site-packages/airflow/cli/commands/task_command.py", line 256, in _run_task_by_selected_method
    return _run_raw_task(args, ti)
           ^^^^^^^^^^^^^^^^^^^^^^^
  File "/home/airflow/.local/lib/python3.12/site-packages/airflow/cli/commands/task_command.py", line 341, in _run_raw_task
    return ti._run_raw_task(
           ^^^^^^^^^^^^^^^^^
  File "/home/airflow/.local/lib/python3.12/site-packages/airflow/utils/session.py", line 97, in wrapper
    return func(*args, session=session, **kwargs)
           ^^^^^^^^^^^^^^^^^^^^^^^^^^^^^^^^^^^^^^
  File "/home/airflow/.local/lib/python3.12/site-packages/airflow/models/taskinstance.py", line 3006, in _run_raw_task
    return _run_raw_task(
           ^^^^^^^^^^^^^^
  File "/home/airflow/.local/lib/python3.12/site-packages/airflow/models/taskinstance.py", line 274, in _run_raw_task
    TaskInstance._execute_task_with_callbacks(
  File "/home/airflow/.local/lib/python3.12/site-packages/airflow/models/taskinstance.py", line 3161, in _execute_task_with_callbacks
    result = self._execute_task(context, task_orig)
             ^^^^^^^^^^^^^^^^^^^^^^^^^^^^^^^^^^^^^^
  File "/home/airflow/.local/lib/python3.12/site-packages/airflow/models/taskinstance.py", line 3185, in _execute_task
    return _execute_task(self, context, task_orig)
           ^^^^^^^^^^^^^^^^^^^^^^^^^^^^^^^^^^^^^^^
  File "/home/airflow/.local/lib/python3.12/site-packages/airflow/models/taskinstance.py", line 768, in _execute_task
    result = _execute_callable(context=context, **execute_callable_kwargs)
             ^^^^^^^^^^^^^^^^^^^^^^^^^^^^^^^^^^^^^^^^^^^^^^^^^^^^^^^^^^^^^
  File "/home/airflow/.local/lib/python3.12/site-packages/airflow/models/taskinstance.py", line 734, in _execute_callable
    return ExecutionCallableRunner(
           ^^^^^^^^^^^^^^^^^^^^^^^^
  File "/home/airflow/.local/lib/python3.12/site-packages/airflow/utils/operator_helpers.py", line 252, in run
    return self.func(*args, **kwargs)
           ^^^^^^^^^^^^^^^^^^^^^^^^^^
  File "/home/airflow/.local/lib/python3.12/site-packages/airflow/models/baseoperator.py", line 424, in wrapper
    return func(self, *args, **kwargs)
           ^^^^^^^^^^^^^^^^^^^^^^^^^^^
  File "/home/airflow/.local/lib/python3.12/site-packages/airflow/operators/python.py", line 238, in execute
    return_value = self.execute_callable()
                   ^^^^^^^^^^^^^^^^^^^^^^^
  File "/home/airflow/.local/lib/python3.12/site-packages/airflow/operators/python.py", line 256, in execute_callable
    return runner.run(*self.op_args, **self.op_kwargs)
           ^^^^^^^^^^^^^^^^^^^^^^^^^^^^^^^^^^^^^^^^^^^
  File "/home/airflow/.local/lib/python3.12/site-packages/airflow/utils/operator_helpers.py", line 252, in run
    return self.func(*args, **kwargs)
           ^^^^^^^^^^^^^^^^^^^^^^^^^^
  File "/opt/airflow/dags/fraud_detection_training_dag.py", line 30, in _train_model
    raise AirflowException(f'Model training failed: {str(e)}')
airflow.exceptions.AirflowException: Model training failed: NoBrokersAvailable
[2025-07-13T14:14:34.439+0000] {local_task_job_runner.py:266} INFO - Task exited with return code 1
[2025-07-13T14:14:34.461+0000] {taskinstance.py:3901} INFO - 0 downstream tasks scheduled from follow-on schedule check
[2025-07-13T14:14:34.463+0000] {local_task_job_runner.py:245} INFO - ::endgroup::
