[2025-07-13T12:03:37.045+0000] {local_task_job_runner.py:123} INFO - ::group::Pre task execution logs
[2025-07-13T12:03:37.070+0000] {taskinstance.py:2614} INFO - Dependencies all met for dep_context=non-requeueable deps ti=<TaskInstance: fraud_detection_training.execute_training manual__2025-07-13T12:03:34.421477+00:00 [queued]>
[2025-07-13T12:03:37.080+0000] {taskinstance.py:2614} INFO - Dependencies all met for dep_context=requeueable deps ti=<TaskInstance: fraud_detection_training.execute_training manual__2025-07-13T12:03:34.421477+00:00 [queued]>
[2025-07-13T12:03:37.081+0000] {taskinstance.py:2867} INFO - Starting attempt 1 of 1
[2025-07-13T12:03:37.097+0000] {taskinstance.py:2890} INFO - Executing <Task(PythonOperator): execute_training> on 2025-07-13 12:03:34.421477+00:00
[2025-07-13T12:03:37.104+0000] {warnings.py:112} WARNING - /home/***/.local/lib/python3.12/site-packages/***/task/task_runner/standard_task_runner.py:70: DeprecationWarning: This process (pid=1088) is multi-threaded, use of fork() may lead to deadlocks in the child.
  pid = os.fork()

[2025-07-13T12:03:37.105+0000] {standard_task_runner.py:72} INFO - Started process 1089 to run task
[2025-07-13T12:03:37.106+0000] {standard_task_runner.py:104} INFO - Running: ['***', 'tasks', 'run', 'fraud_detection_training', 'execute_training', 'manual__2025-07-13T12:03:34.421477+00:00', '--job-id', '25', '--raw', '--subdir', 'DAGS_FOLDER/fraud_detection_training_dag.py', '--cfg-path', '/tmp/tmp28dm69ta']
[2025-07-13T12:03:37.107+0000] {standard_task_runner.py:105} INFO - Job 25: Subtask execute_training
[2025-07-13T12:03:37.159+0000] {task_command.py:467} INFO - Running <TaskInstance: fraud_detection_training.execute_training manual__2025-07-13T12:03:34.421477+00:00 [running]> on host 2d98890b302a
[2025-07-13T12:03:37.286+0000] {taskinstance.py:3134} INFO - Exporting env vars: AIRFLOW_CTX_DAG_OWNER='datamasterylab.com' AIRFLOW_CTX_DAG_ID='fraud_detection_training' AIRFLOW_CTX_TASK_ID='execute_training' AIRFLOW_CTX_EXECUTION_DATE='2025-07-13T12:03:34.421477+00:00' AIRFLOW_CTX_TRY_NUMBER='1' AIRFLOW_CTX_DAG_RUN_ID='manual__2025-07-13T12:03:34.421477+00:00'
[2025-07-13T12:03:37.287+0000] {taskinstance.py:732} INFO - ::endgroup::
[2025-07-13T12:03:40.660+0000] {warnings.py:112} WARNING - /opt/***/dags/fraud_detection_training.py:45: UserWarning: The numpy.array_api submodule is still experimental. See NEP 47.
  from numpy.array_api import astype

[2025-07-13T12:03:40.703+0000] {fraud_detection_training_dag.py:23} INFO - Initializing fraud detection training
[2025-07-13T12:03:40.709+0000] {fraud_detection_training.py:120} INFO - Configuration loaded successfully
[2025-07-13T12:03:41.133+0000] {fraud_detection_training.py:164} INFO - Minio connection verified. Buckets: ['mlflow']
[2025-07-13T12:03:41.249+0000] {fraud_detection_training.py:306} INFO - Starting model training process
[2025-07-13T12:03:41.249+0000] {fraud_detection_training.py:189} INFO - Connecting to kafka topic transactions
[2025-07-13T12:03:41.250+0000] {fraud_detection_training.py:231} ERROR - Failed to read data from Kafka: 'bootstrap_servers'
Traceback (most recent call last):
  File "/opt/airflow/dags/fraud_detection_training.py", line 205, in read_from_kafka
    bootstrap_servers=self.config['bootstrap_servers'].split(','),
                      ~~~~~~~~~~~^^^^^^^^^^^^^^^^^^^^^
KeyError: 'bootstrap_servers'
[2025-07-13T12:03:41.251+0000] {fraud_detection_training.py:467} ERROR - Training failed: 'bootstrap_servers'
Traceback (most recent call last):
  File "/opt/airflow/dags/fraud_detection_training.py", line 309, in train_model
    df = self.read_from_kafka()
         ^^^^^^^^^^^^^^^^^^^^^^
  File "/opt/airflow/dags/fraud_detection_training.py", line 205, in read_from_kafka
    bootstrap_servers=self.config['bootstrap_servers'].split(','),
                      ~~~~~~~~~~~^^^^^^^^^^^^^^^^^^^^^
KeyError: 'bootstrap_servers'
[2025-07-13T12:03:41.252+0000] {fraud_detection_training_dag.py:29} ERROR - Training failed: 'bootstrap_servers'
Traceback (most recent call last):
  File "/opt/airflow/dags/fraud_detection_training_dag.py", line 25, in _train_model
    model, precision = trainer.train_model()
                       ^^^^^^^^^^^^^^^^^^^^^
  File "/opt/airflow/dags/fraud_detection_training.py", line 309, in train_model
    df = self.read_from_kafka()
         ^^^^^^^^^^^^^^^^^^^^^^
  File "/opt/airflow/dags/fraud_detection_training.py", line 205, in read_from_kafka
    bootstrap_servers=self.config['bootstrap_servers'].split(','),
                      ~~~~~~~~~~~^^^^^^^^^^^^^^^^^^^^^
KeyError: 'bootstrap_servers'
[2025-07-13T12:03:41.266+0000] {taskinstance.py:3313} ERROR - Task failed with exception
Traceback (most recent call last):
  File "/opt/airflow/dags/fraud_detection_training_dag.py", line 25, in _train_model
    model, precision = trainer.train_model()
                       ^^^^^^^^^^^^^^^^^^^^^
  File "/opt/airflow/dags/fraud_detection_training.py", line 309, in train_model
    df = self.read_from_kafka()
         ^^^^^^^^^^^^^^^^^^^^^^
  File "/opt/airflow/dags/fraud_detection_training.py", line 205, in read_from_kafka
    bootstrap_servers=self.config['bootstrap_servers'].split(','),
                      ~~~~~~~~~~~^^^^^^^^^^^^^^^^^^^^^
KeyError: 'bootstrap_servers'

During handling of the above exception, another exception occurred:

Traceback (most recent call last):
  File "/home/airflow/.local/lib/python3.12/site-packages/airflow/models/taskinstance.py", line 768, in _execute_task
    result = _execute_callable(context=context, **execute_callable_kwargs)
             ^^^^^^^^^^^^^^^^^^^^^^^^^^^^^^^^^^^^^^^^^^^^^^^^^^^^^^^^^^^^^
  File "/home/airflow/.local/lib/python3.12/site-packages/airflow/models/taskinstance.py", line 734, in _execute_callable
    return ExecutionCallableRunner(
           ^^^^^^^^^^^^^^^^^^^^^^^^
  File "/home/airflow/.local/lib/python3.12/site-packages/airflow/utils/operator_helpers.py", line 252, in run
    return self.func(*args, **kwargs)
           ^^^^^^^^^^^^^^^^^^^^^^^^^^
  File "/home/airflow/.local/lib/python3.12/site-packages/airflow/models/baseoperator.py", line 424, in wrapper
    return func(self, *args, **kwargs)
           ^^^^^^^^^^^^^^^^^^^^^^^^^^^
  File "/home/airflow/.local/lib/python3.12/site-packages/airflow/operators/python.py", line 238, in execute
    return_value = self.execute_callable()
                   ^^^^^^^^^^^^^^^^^^^^^^^
  File "/home/airflow/.local/lib/python3.12/site-packages/airflow/operators/python.py", line 256, in execute_callable
    return runner.run(*self.op_args, **self.op_kwargs)
           ^^^^^^^^^^^^^^^^^^^^^^^^^^^^^^^^^^^^^^^^^^^
  File "/home/airflow/.local/lib/python3.12/site-packages/airflow/utils/operator_helpers.py", line 252, in run
    return self.func(*args, **kwargs)
           ^^^^^^^^^^^^^^^^^^^^^^^^^^
  File "/opt/airflow/dags/fraud_detection_training_dag.py", line 30, in _train_model
    raise AirflowException(f'Model training failed: {str(e)}')
airflow.exceptions.AirflowException: Model training failed: 'bootstrap_servers'
[2025-07-13T12:03:41.271+0000] {taskinstance.py:1226} INFO - Marking task as FAILED. dag_id=fraud_detection_training, task_id=execute_training, run_id=manual__2025-07-13T12:03:34.421477+00:00, execution_date=20250713T120334, start_date=20250713T120337, end_date=20250713T120341
[2025-07-13T12:03:41.300+0000] {taskinstance.py:341} INFO - ::group::Post task execution logs
[2025-07-13T12:03:41.301+0000] {standard_task_runner.py:124} ERROR - Failed to execute job 25 for task execute_training (Model training failed: 'bootstrap_servers'; 1089)
Traceback (most recent call last):
  File "/opt/airflow/dags/fraud_detection_training_dag.py", line 25, in _train_model
    model, precision = trainer.train_model()
                       ^^^^^^^^^^^^^^^^^^^^^
  File "/opt/airflow/dags/fraud_detection_training.py", line 309, in train_model
    df = self.read_from_kafka()
         ^^^^^^^^^^^^^^^^^^^^^^
  File "/opt/airflow/dags/fraud_detection_training.py", line 205, in read_from_kafka
    bootstrap_servers=self.config['bootstrap_servers'].split(','),
                      ~~~~~~~~~~~^^^^^^^^^^^^^^^^^^^^^
KeyError: 'bootstrap_servers'

During handling of the above exception, another exception occurred:

Traceback (most recent call last):
  File "/home/airflow/.local/lib/python3.12/site-packages/airflow/task/task_runner/standard_task_runner.py", line 117, in _start_by_fork
    ret = args.func(args, dag=self.dag)
          ^^^^^^^^^^^^^^^^^^^^^^^^^^^^^
  File "/home/airflow/.local/lib/python3.12/site-packages/airflow/cli/cli_config.py", line 49, in command
    return func(*args, **kwargs)
           ^^^^^^^^^^^^^^^^^^^^^
  File "/home/airflow/.local/lib/python3.12/site-packages/airflow/utils/cli.py", line 116, in wrapper
    return f(*args, **kwargs)
           ^^^^^^^^^^^^^^^^^^
  File "/home/airflow/.local/lib/python3.12/site-packages/airflow/cli/commands/task_command.py", line 483, in task_run
    task_return_code = _run_task_by_selected_method(args, _dag, ti)
                       ^^^^^^^^^^^^^^^^^^^^^^^^^^^^^^^^^^^^^^^^^^^^
  File "/home/airflow/.local/lib/python3.12/site-packages/airflow/cli/commands/task_command.py", line 256, in _run_task_by_selected_method
    return _run_raw_task(args, ti)
           ^^^^^^^^^^^^^^^^^^^^^^^
  File "/home/airflow/.local/lib/python3.12/site-packages/airflow/cli/commands/task_command.py", line 341, in _run_raw_task
    return ti._run_raw_task(
           ^^^^^^^^^^^^^^^^^
  File "/home/airflow/.local/lib/python3.12/site-packages/airflow/utils/session.py", line 97, in wrapper
    return func(*args, session=session, **kwargs)
           ^^^^^^^^^^^^^^^^^^^^^^^^^^^^^^^^^^^^^^
  File "/home/airflow/.local/lib/python3.12/site-packages/airflow/models/taskinstance.py", line 3006, in _run_raw_task
    return _run_raw_task(
           ^^^^^^^^^^^^^^
  File "/home/airflow/.local/lib/python3.12/site-packages/airflow/models/taskinstance.py", line 274, in _run_raw_task
    TaskInstance._execute_task_with_callbacks(
  File "/home/airflow/.local/lib/python3.12/site-packages/airflow/models/taskinstance.py", line 3161, in _execute_task_with_callbacks
    result = self._execute_task(context, task_orig)
             ^^^^^^^^^^^^^^^^^^^^^^^^^^^^^^^^^^^^^^
  File "/home/airflow/.local/lib/python3.12/site-packages/airflow/models/taskinstance.py", line 3185, in _execute_task
    return _execute_task(self, context, task_orig)
           ^^^^^^^^^^^^^^^^^^^^^^^^^^^^^^^^^^^^^^^
  File "/home/airflow/.local/lib/python3.12/site-packages/airflow/models/taskinstance.py", line 768, in _execute_task
    result = _execute_callable(context=context, **execute_callable_kwargs)
             ^^^^^^^^^^^^^^^^^^^^^^^^^^^^^^^^^^^^^^^^^^^^^^^^^^^^^^^^^^^^^
  File "/home/airflow/.local/lib/python3.12/site-packages/airflow/models/taskinstance.py", line 734, in _execute_callable
    return ExecutionCallableRunner(
           ^^^^^^^^^^^^^^^^^^^^^^^^
  File "/home/airflow/.local/lib/python3.12/site-packages/airflow/utils/operator_helpers.py", line 252, in run
    return self.func(*args, **kwargs)
           ^^^^^^^^^^^^^^^^^^^^^^^^^^
  File "/home/airflow/.local/lib/python3.12/site-packages/airflow/models/baseoperator.py", line 424, in wrapper
    return func(self, *args, **kwargs)
           ^^^^^^^^^^^^^^^^^^^^^^^^^^^
  File "/home/airflow/.local/lib/python3.12/site-packages/airflow/operators/python.py", line 238, in execute
    return_value = self.execute_callable()
                   ^^^^^^^^^^^^^^^^^^^^^^^
  File "/home/airflow/.local/lib/python3.12/site-packages/airflow/operators/python.py", line 256, in execute_callable
    return runner.run(*self.op_args, **self.op_kwargs)
           ^^^^^^^^^^^^^^^^^^^^^^^^^^^^^^^^^^^^^^^^^^^
  File "/home/airflow/.local/lib/python3.12/site-packages/airflow/utils/operator_helpers.py", line 252, in run
    return self.func(*args, **kwargs)
           ^^^^^^^^^^^^^^^^^^^^^^^^^^
  File "/opt/airflow/dags/fraud_detection_training_dag.py", line 30, in _train_model
    raise AirflowException(f'Model training failed: {str(e)}')
airflow.exceptions.AirflowException: Model training failed: 'bootstrap_servers'
[2025-07-13T12:03:41.377+0000] {local_task_job_runner.py:266} INFO - Task exited with return code 1
[2025-07-13T12:03:41.405+0000] {taskinstance.py:3901} INFO - 1 downstream tasks scheduled from follow-on schedule check
[2025-07-13T12:03:41.406+0000] {local_task_job_runner.py:245} INFO - ::endgroup::
